<?xml version="1.0"?>
    <robot name="amass">
        <link name="base">
            <inertial>
                <origin xyz="0.002311136 0.23963112 -0.032760162" rpy="0 0 0"/>
                <mass value="0.0001"/>
                <inertia ixx="0.001" ixy="0" ixz="0" iyy="0.001" iyz="0" izz="0.001"/>
            </inertial>
        </link>
        <link name="root">
            <inertial>
                <origin xyz="0 0 0" rpy="0 0 0"/>
                <mass value="5"/>
                <inertia ixx="0.001" ixy="0" ixz="0" iyy="0.001" iyz="0" izz="0.001"/>
            </inertial>
            <collision name="collision_0_root">
                <origin xyz="0.00354 0.065 -0.03107" rpy="0 1.5708 0"/>
                <geometry>
                    <sphere radius="0.05" length="0.115"/>
                </geometry>
            </collision>
            <collision name="collision_1_root">
                <origin xyz="-0.05769 -0.02577 -0.0174" rpy="0 0 0"/>
                <geometry>
                    <sphere radius="0.075"/>
                </geometry>
            </collision>
            <collision name="collision_2_root">
                <origin xyz="0.06735 -0.02415 -0.0174" rpy="0 0 0"/>
                <geometry>
                    <sphere radius="0.075"/>
                </geometry>
            </collision>
        </link>
        <joint name="root" type="floating">
            <origin xyz="0 0 0" rpy="0 0 0"/>
            <parent link="base"/>
            <child link="root"/>
        </joint>
        <link name="lhip_rx">
            <inertial>
                <origin xyz="0 0 0" rpy="0 0 0"/>
                <mass value="0.0001"/>
                <inertia ixx="0.001" ixy="0" ixz="0" iyy="0.001" iyz="0" izz="0.001"/>
            </inertial>
        </link>
        <joint name="lhip_rx" type="revolute">
            <origin xyz="0.07043488 -0.09243184 -0.004805753" rpy="0 0 0"/>
            <parent link="root"/>
            <child link="lhip_rx"/>
            <limit effort="1000.0" lower="-3.14" upper="3.14" velocity="0.5" />
            <axis xyz="1 0 0"/>
        </joint>
        <link name="lhip_ry">
            <inertial>
                <origin xyz="0 0 0" rpy="0 0 0"/>
                <mass value="0.0001"/>
                <inertia ixx="0.001" ixy="0" ixz="0" iyy="0.001" iyz="0" izz="0.001"/>
            </inertial>
        </link>
        <joint name="lhip_ry" type="revolute">
            <origin xyz="0 0 0" rpy="0 0 0"/>
            <parent link="lhip_rx"/>
            <child link="lhip_ry"/>
            <limit effort="1000.0" lower="-3.14" upper="3.14" velocity="0.5" />
            <axis xyz="0 1 0"/>
        </joint>
        <link name="lhip_rz">
            <inertial>
                <origin xyz="0 0 0" rpy="0 0 0"/>
                <mass value="0.0001"/>
                <inertia ixx="0.001" ixy="0" ixz="0" iyy="0.001" iyz="0" izz="0.001"/>
            </inertial>
        </link>
        <joint name="lhip_rz" type="revolute">
            <origin xyz="0 0 0" rpy="0 0 0"/>
            <parent link="lhip_ry"/>
            <child link="lhip_rz"/>
            <limit effort="1000.0" lower="-3.14" upper="3.14" velocity="0.5" />
            <axis xyz="0 0 1"/>
        </joint>
        <link name="lhip">
            <inertial>
                <origin xyz="0.014650244 -0.17404002 -0.0028717956" rpy="0 0 0"/>
                <mass value="5"/>
                <inertia ixx="0.001" ixy="0" ixz="0" iyy="0.001" iyz="0" izz="0.001"/>
            </inertial>
            <collision name="lhip">
                <origin xyz="0.014650244 -0.17404002 -0.0028717956" rpy="1.587295606891168 0.08396808709535009 0.08536337413891969"/>
                <geometry>
                    <capsule radius="0.05" length="0.24935829043388366"/>
                </geometry>
            </collision>
        </link>
        <joint name="lhip" type="fixed">
            <origin xyz="0 0 0" rpy="0 0 0"/>
            <parent link="lhip_rz"/>
            <child link="lhip"/>
        </joint>
        <link name="lknee_rx">
            <inertial>
                <origin xyz="0 0 0" rpy="0 0 0"/>
                <mass value="0.0001"/>
                <inertia ixx="0.001" ixy="0" ixz="0" iyy="0.001" iyz="0" izz="0.001"/>
            </inertial>
        </link>
        <joint name="lknee_rx" type="revolute">
            <origin xyz="0.029300489 -0.34808004 -0.005743591" rpy="0 0 0"/>
            <parent link="lhip"/>
            <child link="lknee_rx"/>
            <limit effort="1000.0" lower="-3.14" upper="3.14" velocity="0.5" />
            <axis xyz="1 0 0"/>
        </joint>
        <link name="lknee_ry">
            <inertial>
                <origin xyz="0 0 0" rpy="0 0 0"/>
                <mass value="0.0001"/>
                <inertia ixx="0.001" ixy="0" ixz="0" iyy="0.001" iyz="0" izz="0.001"/>
            </inertial>
        </link>
        <joint name="lknee_ry" type="revolute">
            <origin xyz="0 0 0" rpy="0 0 0"/>
            <parent link="lknee_rx"/>
            <child link="lknee_ry"/>
            <limit effort="1000.0" lower="-3.14" upper="3.14" velocity="0.5" />
            <axis xyz="0 1 0"/>
        </joint>
        <link name="lknee_rz">
            <inertial>
                <origin xyz="0 0 0" rpy="0 0 0"/>
                <mass value="0.0001"/>
                <inertia ixx="0.001" ixy="0" ixz="0" iyy="0.001" iyz="0" izz="0.001"/>
            </inertial>
        </link>
        <joint name="lknee_rz" type="revolute">
            <origin xyz="0 0 0" rpy="0 0 0"/>
            <parent link="lknee_ry"/>
            <child link="lknee_rz"/>
            <limit effort="1000.0" lower="-3.14" upper="3.14" velocity="0.5" />
            <axis xyz="0 0 1"/>
        </joint>
        <link name="lknee">
            <inertial>
                <origin xyz="-0.007021744 -0.18554145 -0.021956526" rpy="0 0 0"/>
                <mass value="3"/>
                <inertia ixx="0.001" ixy="0" ixz="0" iyy="0.001" iyz="0" izz="0.001"/>
            </inertial>
            <collision name="lknee">
                <origin xyz="-0.007021744 -0.18554145 -0.021956526" rpy="1.688586102850629 -0.03756469769018911 -0.04227079851220909"/>
                <geometry>
                    <capsule radius="0.05" length="0.27393596768379214"/>
                </geometry>
            </collision>
        </link>
        <joint name="lknee" type="fixed">
            <origin xyz="0 0 0" rpy="0 0 0"/>
            <parent link="lknee_rz"/>
            <child link="lknee"/>
        </joint>
        <link name="lankle_rx">
            <inertial>
                <origin xyz="0 0 0" rpy="0 0 0"/>
                <mass value="0.0001"/>
                <inertia ixx="0.001" ixy="0" ixz="0" iyy="0.001" iyz="0" izz="0.001"/>
            </inertial>
        </link>
        <joint name="lankle_rx" type="revolute">
            <origin xyz="-0.014043488 -0.3710829 -0.04391305" rpy="0 0 0"/>
            <parent link="lknee"/>
            <child link="lankle_rx"/>
            <limit effort="1000.0" lower="-3.14" upper="3.14" velocity="0.5" />
            <axis xyz="1 0 0"/>
        </joint>
        <link name="lankle_ry">
            <inertial>
                <origin xyz="0 0 0" rpy="0 0 0"/>
                <mass value="0.0001"/>
                <inertia ixx="0.001" ixy="0" ixz="0" iyy="0.001" iyz="0" izz="0.001"/>
            </inertial>
        </link>
        <joint name="lankle_ry" type="revolute">
            <origin xyz="0 0 0" rpy="0 0 0"/>
            <parent link="lankle_rx"/>
            <child link="lankle_ry"/>
            <limit effort="1000.0" lower="-3.14" upper="3.14" velocity="0.5" />
            <axis xyz="0 1 0"/>
        </joint>
        <link name="lankle_rz">
            <inertial>
                <origin xyz="0 0 0" rpy="0 0 0"/>
                <mass value="0.0001"/>
                <inertia ixx="0.001" ixy="0" ixz="0" iyy="0.001" iyz="0" izz="0.001"/>
            </inertial>
        </link>
        <joint name="lankle_rz" type="revolute">
            <origin xyz="0 0 0" rpy="0 0 0"/>
            <parent link="lankle_ry"/>
            <child link="lankle_rz"/>
            <limit effort="1000.0" lower="-3.14" upper="3.14" velocity="0.5" />
            <axis xyz="0 0 1"/>
        </joint>
        <link name="lankle">
            <inertial>
                <origin xyz="0.01719 -0.06032 0.02617" rpy="0 0 0"/>
                <mass value="1"/>
                <inertia ixx="0.001" ixy="0" ixz="0" iyy="0.001" iyz="0" izz="0.001"/>
            </inertial>
            <collision name="lankle">
                <origin xyz="0.01719 -0.06032 0.02617" rpy="0 0 0"/>
                <geometry>
                    <box size="0.0875 0.06 0.185"/>
                </geometry>
            </collision>
        </link>
        <joint name="lankle" type="fixed">
            <origin xyz="0 0 0" rpy="0 0 0"/>
            <parent link="lankle_rz"/>
            <child link="lankle"/>
        </joint>
        <link name="rhip_rx">
            <inertial>
                <origin xyz="0 0 0" rpy="0 0 0"/>
                <mass value="0.0001"/>
                <inertia ixx="0.001" ixy="0" ixz="0" iyy="0.001" iyz="0" izz="0.001"/>
            </inertial>
        </link>
        <joint name="rhip_rx" type="revolute">
            <origin xyz="-0.06890478 -0.091423005 -0.0021150652" rpy="0 0 0"/>
            <parent link="root"/>
            <child link="rhip_rx"/>
            <limit effort="1000.0" lower="-3.14" upper="3.14" velocity="0.5" />
            <axis xyz="1 0 0"/>
        </joint>
        <link name="rhip_ry">
            <inertial>
                <origin xyz="0 0 0" rpy="0 0 0"/>
                <mass value="0.0001"/>
                <inertia ixx="0.001" ixy="0" ixz="0" iyy="0.001" iyz="0" izz="0.001"/>
            </inertial>
        </link>
        <joint name="rhip_ry" type="revolute">
            <origin xyz="0 0 0" rpy="0 0 0"/>
            <parent link="rhip_rx"/>
            <child link="rhip_ry"/>
            <limit effort="1000.0" lower="-3.14" upper="3.14" velocity="0.5" />
            <axis xyz="0 1 0"/>
        </joint>
        <link name="rhip_rz">
            <inertial>
                <origin xyz="0 0 0" rpy="0 0 0"/>
                <mass value="0.0001"/>
                <inertia ixx="0.001" ixy="0" ixz="0" iyy="0.001" iyz="0" izz="0.001"/>
            </inertial>
        </link>
        <joint name="rhip_rz" type="revolute">
            <origin xyz="0 0 0" rpy="0 0 0"/>
            <parent link="rhip_ry"/>
            <child link="rhip_rz"/>
            <limit effort="1000.0" lower="-3.14" upper="3.14" velocity="0.5" />
            <axis xyz="0 0 1"/>
        </joint>
        <link name="rhip">
            <inertial>
                <origin xyz="-0.016308166 -0.1786979 -0.004939965" rpy="0 0 0"/>
                <mass value="5"/>
                <inertia ixx="0.001" ixy="0" ixz="0" iyy="0.001" iyz="0" izz="0.001"/>
            </inertial>
            <collision name="rhip">
                <origin xyz="-0.016308166 -0.1786979 -0.004939965" rpy="1.5984335132624603 -0.09097443247417147 -0.09352044055333736"/>
                <geometry>
                    <capsule radius="0.05" length="0.25901698470115664"/>
                </geometry>
            </collision>
        </link>
        <joint name="rhip" type="fixed">
            <origin xyz="0 0 0" rpy="0 0 0"/>
            <parent link="rhip_rz"/>
            <child link="rhip"/>
        </joint>
        <link name="rknee_rx">
            <inertial>
                <origin xyz="0 0 0" rpy="0 0 0"/>
                <mass value="0.0001"/>
                <inertia ixx="0.001" ixy="0" ixz="0" iyy="0.001" iyz="0" izz="0.001"/>
            </inertial>
        </link>
        <joint name="rknee_rx" type="revolute">
            <origin xyz="-0.032616332 -0.3573958 -0.00987993" rpy="0 0 0"/>
            <parent link="rhip"/>
            <child link="rknee_rx"/>
            <limit effort="1000.0" lower="-3.14" upper="3.14" velocity="0.5" />
            <axis xyz="1 0 0"/>
        </joint>
        <link name="rknee_ry">
            <inertial>
                <origin xyz="0 0 0" rpy="0 0 0"/>
                <mass value="0.0001"/>
                <inertia ixx="0.001" ixy="0" ixz="0" iyy="0.001" iyz="0" izz="0.001"/>
            </inertial>
        </link>
        <joint name="rknee_ry" type="revolute">
            <origin xyz="0 0 0" rpy="0 0 0"/>
            <parent link="rknee_rx"/>
            <child link="rknee_ry"/>
            <limit effort="1000.0" lower="-3.14" upper="3.14" velocity="0.5" />
            <axis xyz="0 1 0"/>
        </joint>
        <link name="rknee_rz">
            <inertial>
                <origin xyz="0 0 0" rpy="0 0 0"/>
                <mass value="0.0001"/>
                <inertia ixx="0.001" ixy="0" ixz="0" iyy="0.001" iyz="0" izz="0.001"/>
            </inertial>
        </link>
        <joint name="rknee_rz" type="revolute">
            <origin xyz="0 0 0" rpy="0 0 0"/>
            <parent link="rknee_ry"/>
            <child link="rknee_rz"/>
            <limit effort="1000.0" lower="-3.14" upper="3.14" velocity="0.5" />
            <axis xyz="0 0 1"/>
        </joint>
        <link name="rknee">
            <inertial>
                <origin xyz="0.007867672 -0.18599537 -0.021468703" rpy="0 0 0"/>
                <mass value="3"/>
                <inertia ixx="0.001" ixy="0" ixz="0" iyy="0.001" iyz="0" izz="0.001"/>
            </inertial>
            <collision name="rknee">
                <origin xyz="0.007867672 -0.18599537 -0.021468703" rpy="1.6857137775779043 0.04199665232500105 0.047121202787288076"/>
                <geometry>
                    <capsule radius="0.05" length="0.2747910559177399"/>
                </geometry>
            </collision>
        </link>
        <joint name="rknee" type="fixed">
            <origin xyz="0 0 0" rpy="0 0 0"/>
            <parent link="rknee_rz"/>
            <child link="rknee"/>
        </joint>
        <link name="rankle_rx">
            <inertial>
                <origin xyz="0 0 0" rpy="0 0 0"/>
                <mass value="0.0001"/>
                <inertia ixx="0.001" ixy="0" ixz="0" iyy="0.001" iyz="0" izz="0.001"/>
            </inertial>
        </link>
        <joint name="rankle_rx" type="revolute">
            <origin xyz="0.015735343 -0.37199074 -0.042937405" rpy="0 0 0"/>
            <parent link="rknee"/>
            <child link="rankle_rx"/>
            <limit effort="1000.0" lower="-3.14" upper="3.14" velocity="0.5" />
            <axis xyz="1 0 0"/>
        </joint>
        <link name="rankle_ry">
            <inertial>
                <origin xyz="0 0 0" rpy="0 0 0"/>
                <mass value="0.0001"/>
                <inertia ixx="0.001" ixy="0" ixz="0" iyy="0.001" iyz="0" izz="0.001"/>
            </inertial>
        </link>
        <joint name="rankle_ry" type="revolute">
            <origin xyz="0 0 0" rpy="0 0 0"/>
            <parent link="rankle_rx"/>
            <child link="rankle_ry"/>
            <limit effort="1000.0" lower="-3.14" upper="3.14" velocity="0.5" />
            <axis xyz="0 1 0"/>
        </joint>
        <link name="rankle_rz">
            <inertial>
                <origin xyz="0 0 0" rpy="0 0 0"/>
                <mass value="0.0001"/>
                <inertia ixx="0.001" ixy="0" ixz="0" iyy="0.001" iyz="0" izz="0.001"/>
            </inertial>
        </link>
        <joint name="rankle_rz" type="revolute">
            <origin xyz="0 0 0" rpy="0 0 0"/>
            <parent link="rankle_ry"/>
            <child link="rankle_rz"/>
            <limit effort="1000.0" lower="-3.14" upper="3.14" velocity="0.5" />
            <axis xyz="0 0 1"/>
        </joint>
        <link name="rankle">
            <inertial>
                <origin xyz="-0.01719 -0.06032 0.02617" rpy="0 0 0"/>
                <mass value="1"/>
                <inertia ixx="0.001" ixy="0" ixz="0" iyy="0.001" iyz="0" izz="0.001"/>
            </inertial>
            <collision name="rankle">
                <origin xyz="-0.01719 -0.06032 0.02617" rpy="0 0 0"/>
                <geometry>
                    <box size="0.0875 0.06 0.185"/>
                </geometry>
            </collision>
        </link>
        <joint name="rankle" type="fixed">
            <origin xyz="0 0 0" rpy="0 0 0"/>
            <parent link="rankle_rz"/>
            <child link="rankle"/>
        </joint>
        <link name="lowerback_rx">
            <inertial>
                <origin xyz="0 0 0" rpy="0 0 0"/>
                <mass value="0.0001"/>
                <inertia ixx="0.001" ixy="0" ixz="0" iyy="0.001" iyz="0" izz="0.001"/>
            </inertial>
        </link>
        <joint name="lowerback_rx" type="revolute">
            <origin xyz="-0.0024732477 0.11192909 -0.031253766" rpy="0 0 0"/>
            <parent link="root"/>
            <child link="lowerback_rx"/>
            <limit effort="1000.0" lower="-3.14" upper="3.14" velocity="0.5" />
            <axis xyz="1 0 0"/>
        </joint>
        <link name="lowerback_ry">
            <inertial>
                <origin xyz="0 0 0" rpy="0 0 0"/>
                <mass value="0.0001"/>
                <inertia ixx="0.001" ixy="0" ixz="0" iyy="0.001" iyz="0" izz="0.001"/>
            </inertial>
        </link>
        <joint name="lowerback_ry" type="revolute">
            <origin xyz="0 0 0" rpy="0 0 0"/>
            <parent link="lowerback_rx"/>
            <child link="lowerback_ry"/>
            <limit effort="1000.0" lower="-3.14" upper="3.14" velocity="0.5" />
            <axis xyz="0 1 0"/>
        </joint>
        <link name="lowerback_rz">
            <inertial>
                <origin xyz="0 0 0" rpy="0 0 0"/>
                <mass value="0.0001"/>
                <inertia ixx="0.001" ixy="0" ixz="0" iyy="0.001" iyz="0" izz="0.001"/>
            </inertial>
        </link>
        <joint name="lowerback_rz" type="revolute">
            <origin xyz="0 0 0" rpy="0 0 0"/>
            <parent link="lowerback_ry"/>
            <child link="lowerback_rz"/>
            <limit effort="1000.0" lower="-3.14" upper="3.14" velocity="0.5" />
            <axis xyz="0 0 1"/>
        </joint>
        <link name="lowerback">
            <inertial>
                <origin xyz="0.0 0.05 0.013" rpy="0 0 0"/>
                <mass value="5"/>
                <inertia ixx="0.001" ixy="0" ixz="0" iyy="0.001" iyz="0" izz="0.001"/>
            </inertial>
            <collision name="lowerback">
                <origin xyz="0.0 0.05 0.013" rpy="0 0 0"/>
                <geometry>
                    <sphere radius="0.065"/>
                </geometry>
            </collision>
        </link>
        <joint name="lowerback" type="fixed">
            <origin xyz="0 0 0" rpy="0 0 0"/>
            <parent link="lowerback_rz"/>
            <child link="lowerback"/>
        </joint>
        <link name="upperback_rx">
            <inertial>
                <origin xyz="0 0 0" rpy="0 0 0"/>
                <mass value="0.0001"/>
                <inertia ixx="0.001" ixy="0" ixz="0" iyy="0.001" iyz="0" izz="0.001"/>
            </inertial>
        </link>
        <joint name="upperback_rx" type="revolute">
            <origin xyz="0.0061939117 0.14058295 0.000105334446" rpy="0 0 0"/>
            <parent link="lowerback"/>
            <child link="upperback_rx"/>
            <limit effort="1000.0" lower="-3.14" upper="3.14" velocity="0.5" />
            <axis xyz="1 0 0"/>
        </joint>
        <link name="upperback_ry">
            <inertial>
                <origin xyz="0 0 0" rpy="0 0 0"/>
                <mass value="0.0001"/>
                <inertia ixx="0.001" ixy="0" ixz="0" iyy="0.001" iyz="0" izz="0.001"/>
            </inertial>
        </link>
        <joint name="upperback_ry" type="revolute">
            <origin xyz="0 0 0" rpy="0 0 0"/>
            <parent link="upperback_rx"/>
            <child link="upperback_ry"/>
            <limit effort="1000.0" lower="-3.14" upper="3.14" velocity="0.5" />
            <axis xyz="0 1 0"/>
        </joint>
        <link name="upperback_rz">
            <inertial>
                <origin xyz="0 0 0" rpy="0 0 0"/>
                <mass value="0.0001"/>
                <inertia ixx="0.001" ixy="0" ixz="0" iyy="0.001" iyz="0" izz="0.001"/>
            </inertial>
        </link>
        <joint name="upperback_rz" type="revolute">
            <origin xyz="0 0 0" rpy="0 0 0"/>
            <parent link="upperback_ry"/>
            <child link="upperback_rz"/>
            <limit effort="1000.0" lower="-3.14" upper="3.14" velocity="0.5" />
            <axis xyz="0 0 1"/>
        </joint>
        <link name="upperback">
            <inertial>
                <origin xyz="0.0 0.02246 0.00143" rpy="0 0 0"/>
                <mass value="5"/>
                <inertia ixx="0.001" ixy="0" ixz="0" iyy="0.001" iyz="0" izz="0.001"/>
            </inertial>
            <collision name="upperback">
                <origin xyz="0.0 0.02246 0.00143" rpy="0 0 0"/>
                <geometry>
                    <sphere radius="0.05"/>
                </geometry>
            </collision>
        </link>
        <joint name="upperback" type="fixed">
            <origin xyz="0 0 0" rpy="0 0 0"/>
            <parent link="upperback_rz"/>
            <child link="upperback"/>
        </joint>
        <link name="chest_rx">
            <inertial>
                <origin xyz="0 0 0" rpy="0 0 0"/>
                <mass value="0.0001"/>
                <inertia ixx="0.001" ixy="0" ixz="0" iyy="0.001" iyz="0" izz="0.001"/>
            </inertial>
        </link>
        <joint name="chest_rx" type="revolute">
            <origin xyz="0.0014724908 0.055514276 0.027504113" rpy="0 0 0"/>
            <parent link="upperback"/>
            <child link="chest_rx"/>
            <limit effort="1000.0" lower="-3.14" upper="3.14" velocity="0.5" />
            <axis xyz="1 0 0"/>
        </joint>
        <link name="chest_ry">
            <inertial>
                <origin xyz="0 0 0" rpy="0 0 0"/>
                <mass value="0.0001"/>
                <inertia ixx="0.001" ixy="0" ixz="0" iyy="0.001" iyz="0" izz="0.001"/>
            </inertial>
        </link>
        <joint name="chest_ry" type="revolute">
            <origin xyz="0 0 0" rpy="0 0 0"/>
            <parent link="chest_rx"/>
            <child link="chest_ry"/>
            <limit effort="1000.0" lower="-3.14" upper="3.14" velocity="0.5" />
            <axis xyz="0 1 0"/>
        </joint>
        <link name="chest_rz">
            <inertial>
                <origin xyz="0 0 0" rpy="0 0 0"/>
                <mass value="0.0001"/>
                <inertia ixx="0.001" ixy="0" ixz="0" iyy="0.001" iyz="0" izz="0.001"/>
            </inertial>
        </link>
        <joint name="chest_rz" type="revolute">
            <origin xyz="0 0 0" rpy="0 0 0"/>
            <parent link="chest_ry"/>
            <child link="chest_rz"/>
            <limit effort="1000.0" lower="-3.14" upper="3.14" velocity="0.5" />
            <axis xyz="0 0 1"/>
        </joint>
        <link name="chest">
            <inertial>
                <origin xyz="0.0 0.057 -0.00687" rpy="0 0 0"/>
                <mass value="8"/>
                <inertia ixx="0.001" ixy="0" ixz="0" iyy="0.001" iyz="0" izz="0.001"/>
            </inertial>
            <collision name="chest0">
                <origin xyz="0.045 0.057 -0.00687" rpy="0 0 0"/>
                <geometry>
                    <sphere radius="0.07"/>
                </geometry>
            </collision>
            <collision name="chest1">
                <origin xyz="-0.045 0.057 -0.00687" rpy="0 0 0"/>
                <geometry>
                    <sphere radius="0.07"/>
                </geometry>
            </collision>
        </link>
        <joint name="chest" type="fixed">
            <origin xyz="0 0 0" rpy="0 0 0"/>
            <parent link="chest_rz"/>
            <child link="chest"/>
        </joint>
        <link name="lowerneck_rx">
            <inertial>
                <origin xyz="0 0 0" rpy="0 0 0"/>
                <mass value="0.0001"/>
                <inertia ixx="0.001" ixy="0" ixz="0" iyy="0.001" iyz="0" izz="0.001"/>
            </inertial>
        </link>
        <joint name="lowerneck_rx" type="revolute">
            <origin xyz="-0.0025418848 0.21677491 -0.047999304" rpy="0 0 0"/>
            <parent link="chest"/>
            <child link="lowerneck_rx"/>
            <limit effort="1000.0" lower="-3.14" upper="3.14" velocity="0.5" />
            <axis xyz="1 0 0"/>
        </joint>
        <link name="lowerneck_ry">
            <inertial>
                <origin xyz="0 0 0" rpy="0 0 0"/>
                <mass value="0.0001"/>
                <inertia ixx="0.001" ixy="0" ixz="0" iyy="0.001" iyz="0" izz="0.001"/>
            </inertial>
        </link>
        <joint name="lowerneck_ry" type="revolute">
            <origin xyz="0 0 0" rpy="0 0 0"/>
            <parent link="lowerneck_rx"/>
            <child link="lowerneck_ry"/>
            <limit effort="1000.0" lower="-3.14" upper="3.14" velocity="0.5" />
            <axis xyz="0 1 0"/>
        </joint>
        <link name="lowerneck_rz">
            <inertial>
                <origin xyz="0 0 0" rpy="0 0 0"/>
                <mass value="0.0001"/>
                <inertia ixx="0.001" ixy="0" ixz="0" iyy="0.001" iyz="0" izz="0.001"/>
            </inertial>
        </link>
        <joint name="lowerneck_rz" type="revolute">
            <origin xyz="0 0 0" rpy="0 0 0"/>
            <parent link="lowerneck_ry"/>
            <child link="lowerneck_rz"/>
            <limit effort="1000.0" lower="-3.14" upper="3.14" velocity="0.5" />
            <axis xyz="0 0 1"/>
        </joint>
        <link name="lowerneck">
            <inertial>
                <origin xyz="0 -0.05577153652906418 0.047999304" rpy="0 0 0"/>
                <mass value="0.5"/>
                <inertia ixx="0.001" ixy="0" ixz="0" iyy="0.001" iyz="0" izz="0.001"/>
            </inertial>
            <collision name="lowerneck">
                <origin xyz="0 -0.05577153652906418 0.047999304" rpy="-1.5707963267948966 0.0 0.0"/>
                <geometry>
                    <capsule radius="0.03" length="0.02154307305812836"/>
                </geometry>
            </collision>
        </link>
        <joint name="lowerneck" type="fixed">
            <origin xyz="0 0 0" rpy="0 0 0"/>
            <parent link="lowerneck_rz"/>
            <child link="lowerneck"/>
        </joint>
        <link name="upperneck_rx">
            <inertial>
                <origin xyz="0 0 0" rpy="0 0 0"/>
                <mass value="0.0001"/>
                <inertia ixx="0.001" ixy="0" ixz="0" iyy="0.001" iyz="0" izz="0.001"/>
            </inertial>
        </link>
        <joint name="upperneck_rx" type="revolute">
            <origin xyz="0.0051423274 0.06356296 0.050819084" rpy="0 0 0"/>
            <parent link="lowerneck"/>
            <child link="upperneck_rx"/>
            <limit effort="1000.0" lower="-3.14" upper="3.14" velocity="0.5" />
            <axis xyz="1 0 0"/>
        </joint>
        <link name="upperneck_ry">
            <inertial>
                <origin xyz="0 0 0" rpy="0 0 0"/>
                <mass value="0.0001"/>
                <inertia ixx="0.001" ixy="0" ixz="0" iyy="0.001" iyz="0" izz="0.001"/>
            </inertial>
        </link>
        <joint name="upperneck_ry" type="revolute">
            <origin xyz="0 0 0" rpy="0 0 0"/>
            <parent link="upperneck_rx"/>
            <child link="upperneck_ry"/>
            <limit effort="1000.0" lower="-3.14" upper="3.14" velocity="0.5" />
            <axis xyz="0 1 0"/>
        </joint>
        <link name="upperneck_rz">
            <inertial>
                <origin xyz="0 0 0" rpy="0 0 0"/>
                <mass value="0.0001"/>
                <inertia ixx="0.001" ixy="0" ixz="0" iyy="0.001" iyz="0" izz="0.001"/>
            </inertial>
        </link>
        <joint name="upperneck_rz" type="revolute">
            <origin xyz="0 0 0" rpy="0 0 0"/>
            <parent link="upperneck_ry"/>
            <child link="upperneck_rz"/>
            <limit effort="1000.0" lower="-3.14" upper="3.14" velocity="0.5" />
            <axis xyz="0 0 1"/>
        </joint>
        <link name="upperneck">
            <inertial>
                <origin xyz="0 0 0" rpy="0 0 0"/>
                <mass value="3"/>
                <inertia ixx="0.001" ixy="0" ixz="0" iyy="0.001" iyz="0" izz="0.001"/>
            </inertial>
            <collision name="upperneck">
                <origin xyz="0 0 0" rpy="-1.5707963267948966 0.0 0.0"/>
                <geometry>
                    <capsule radius="0.06" length="0.035"/>
                </geometry>
            </collision>
        </link>
        <joint name="upperneck" type="fixed">
            <origin xyz="0 0 0" rpy="0 0 0"/>
            <parent link="upperneck_rz"/>
            <child link="upperneck"/>
        </joint>
        <link name="lclavicle_rx">
            <inertial>
                <origin xyz="0 0 0" rpy="0 0 0"/>
                <mass value="0.0001"/>
                <inertia ixx="0.001" ixy="0" ixz="0" iyy="0.001" iyz="0" izz="0.001"/>
            </inertial>
        </link>
        <joint name="lclavicle_rx" type="revolute">
            <origin xyz="0.08181205 0.12415768 -0.035220474" rpy="0 0 0"/>
            <parent link="chest"/>
            <child link="lclavicle_rx"/>
            <limit effort="1000.0" lower="-3.14" upper="3.14" velocity="0.5" />
            <axis xyz="1 0 0"/>
        </joint>
        <link name="lclavicle_ry">
            <inertial>
                <origin xyz="0 0 0" rpy="0 0 0"/>
                <mass value="0.0001"/>
                <inertia ixx="0.001" ixy="0" ixz="0" iyy="0.001" iyz="0" izz="0.001"/>
            </inertial>
        </link>
        <joint name="lclavicle_ry" type="revolute">
            <origin xyz="0 0 0" rpy="0 0 0"/>
            <parent link="lclavicle_rx"/>
            <child link="lclavicle_ry"/>
            <limit effort="1000.0" lower="-3.14" upper="3.14" velocity="0.5" />
            <axis xyz="0 1 0"/>
        </joint>
        <link name="lclavicle_rz">
            <inertial>
                <origin xyz="0 0 0" rpy="0 0 0"/>
                <mass value="0.0001"/>
                <inertia ixx="0.001" ixy="0" ixz="0" iyy="0.001" iyz="0" izz="0.001"/>
            </inertial>
        </link>
        <joint name="lclavicle_rz" type="revolute">
            <origin xyz="0 0 0" rpy="0 0 0"/>
            <parent link="lclavicle_ry"/>
            <child link="lclavicle_rz"/>
            <limit effort="1000.0" lower="-3.14" upper="3.14" velocity="0.5" />
            <axis xyz="0 0 1"/>
        </joint>
        <link name="lclavicle">
            <inertial>
                <origin xyz="0.047521573 0.013804935 -0.005315164" rpy="0 0 0"/>
                <mass value="1"/>
                <inertia ixx="0.001" ixy="0" ixz="0" iyy="0.001" iyz="0" izz="0.001"/>
            </inertial>
            <collision name="lclavicle">
                <origin xyz="0.047521573 0.013804935 -0.005315164" rpy="-1.9383218243825908 1.2690176665005133 -1.6403641073651287"/>
                <geometry>
                    <capsule radius="0.04" length="0.019541492760181425"/>
                </geometry>
            </collision>
        </link>
        <joint name="lclavicle" type="fixed">
            <origin xyz="0 0 0" rpy="0 0 0"/>
            <parent link="lclavicle_rz"/>
            <child link="lclavicle"/>
        </joint>
        <link name="lshoulder_rx">
            <inertial>
                <origin xyz="0 0 0" rpy="0 0 0"/>
                <mass value="0.0001"/>
                <inertia ixx="0.001" ixy="0" ixz="0" iyy="0.001" iyz="0" izz="0.001"/>
            </inertial>
        </link>
        <joint name="lshoulder_rx" type="revolute">
            <origin xyz="0.095043145 0.02760987 -0.010630328" rpy="0 0 0"/>
            <parent link="lclavicle"/>
            <child link="lshoulder_rx"/>
            <limit effort="1000.0" lower="-3.14" upper="3.14" velocity="0.5" />
            <axis xyz="1 0 0"/>
        </joint>
        <link name="lshoulder_ry">
            <inertial>
                <origin xyz="0 0 0" rpy="0 0 0"/>
                <mass value="0.0001"/>
                <inertia ixx="0.001" ixy="0" ixz="0" iyy="0.001" iyz="0" izz="0.001"/>
            </inertial>
        </link>
        <joint name="lshoulder_ry" type="revolute">
            <origin xyz="0 0 0" rpy="0 0 0"/>
            <parent link="lshoulder_rx"/>
            <child link="lshoulder_ry"/>
            <limit effort="1000.0" lower="-3.14" upper="3.14" velocity="0.5" />
            <axis xyz="0 1 0"/>
        </joint>
        <link name="lshoulder_rz">
            <inertial>
                <origin xyz="0 0 0" rpy="0 0 0"/>
                <mass value="0.0001"/>
                <inertia ixx="0.001" ixy="0" ixz="0" iyy="0.001" iyz="0" izz="0.001"/>
            </inertial>
        </link>
        <joint name="lshoulder_rz" type="revolute">
            <origin xyz="0 0 0" rpy="0 0 0"/>
            <parent link="lshoulder_ry"/>
            <child link="lshoulder_rz"/>
            <limit effort="1000.0" lower="-3.14" upper="3.14" velocity="0.5" />
            <axis xyz="0 0 1"/>
        </joint>
        <link name="lshoulder">
            <inertial>
                <origin xyz="0.12361887 -0.004426405 -0.013728489" rpy="0 0 0"/>
                <mass value="2"/>
                <inertia ixx="0.001" ixy="0" ixz="0" iyy="0.001" iyz="0" izz="0.001"/>
            </inertial>
            <collision name="lshoulder">
                <origin xyz="0.12361887 -0.004426405 -0.013728489" rpy="0 0 0"/>
                <geometry>
                    <box size="0.2289151656627655 0.05 0.05"/>
                </geometry>
            </collision>
        </link>
        <joint name="lshoulder" type="fixed">
            <origin xyz="0 0 0" rpy="0 0 0"/>
            <parent link="lshoulder_rz"/>
            <child link="lshoulder"/>
        </joint>
        <link name="lelbow_rx">
            <inertial>
                <origin xyz="0 0 0" rpy="0 0 0"/>
                <mass value="0.0001"/>
                <inertia ixx="0.001" ixy="0" ixz="0" iyy="0.001" iyz="0" izz="0.001"/>
            </inertial>
        </link>
        <joint name="lelbow_rx" type="revolute">
            <origin xyz="0.24723774 -0.00885281 -0.027456978" rpy="0 0 0"/>
            <parent link="lshoulder"/>
            <child link="lelbow_rx"/>
            <limit effort="1000.0" lower="-3.14" upper="3.14" velocity="0.5" />
            <axis xyz="1 0 0"/>
        </joint>
        <link name="lelbow_ry">
            <inertial>
                <origin xyz="0 0 0" rpy="0 0 0"/>
                <mass value="0.0001"/>
                <inertia ixx="0.001" ixy="0" ixz="0" iyy="0.001" iyz="0" izz="0.001"/>
            </inertial>
        </link>
        <joint name="lelbow_ry" type="revolute">
            <origin xyz="0 0 0" rpy="0 0 0"/>
            <parent link="lelbow_rx"/>
            <child link="lelbow_ry"/>
            <limit effort="1000.0" lower="-3.14" upper="3.14" velocity="0.5" />
            <axis xyz="0 1 0"/>
        </joint>
        <link name="lelbow_rz">
            <inertial>
                <origin xyz="0 0 0" rpy="0 0 0"/>
                <mass value="0.0001"/>
                <inertia ixx="0.001" ixy="0" ixz="0" iyy="0.001" iyz="0" izz="0.001"/>
            </inertial>
        </link>
        <joint name="lelbow_rz" type="revolute">
            <origin xyz="0 0 0" rpy="0 0 0"/>
            <parent link="lelbow_ry"/>
            <child link="lelbow_rz"/>
            <limit effort="1000.0" lower="-3.14" upper="3.14" velocity="0.5" />
            <axis xyz="0 0 1"/>
        </joint>
        <link name="lelbow">
            <inertial>
                <origin xyz="0.11943865 0.0037674159 -0.00022526272" rpy="0 0 0"/>
                <mass value="1"/>
                <inertia ixx="0.001" ixy="0" ixz="0" iyy="0.001" iyz="0" izz="0.001"/>
            </inertial>
            <collision name="lelbow">
                <origin xyz="0.11943865 0.0037674159 -0.00022526272" rpy="0 0 0"/>
                <geometry>
                    <box size="0.2189965206384659 0.05 0.05"/>
                </geometry>
            </collision>
        </link>
        <joint name="lelbow" type="fixed">
            <origin xyz="0 0 0" rpy="0 0 0"/>
            <parent link="lelbow_rz"/>
            <child link="lelbow"/>
        </joint>
        <link name="lwrist_rx">
            <inertial>
                <origin xyz="0 0 0" rpy="0 0 0"/>
                <mass value="0.0001"/>
                <inertia ixx="0.001" ixy="0" ixz="0" iyy="0.001" iyz="0" izz="0.001"/>
            </inertial>
        </link>
        <joint name="lwrist_rx" type="fixed">
            <origin xyz="0.2388773 0.0075348318 -0.00045052543" rpy="0 0 0"/>
            <parent link="lelbow"/>
            <child link="lwrist_rx"/>
        </joint>
        <link name="lwrist_ry">
            <inertial>
                <origin xyz="0 0 0" rpy="0 0 0"/>
                <mass value="0.0001"/>
                <inertia ixx="0.001" ixy="0" ixz="0" iyy="0.001" iyz="0" izz="0.001"/>
            </inertial>
        </link>
        <joint name="lwrist_ry" type="fixed">
            <origin xyz="0 0 0" rpy="0 0 0"/>
            <parent link="lwrist_rx"/>
            <child link="lwrist_ry"/>
        </joint>
        <link name="lwrist_rz">
            <inertial>
                <origin xyz="0 0 0" rpy="0 0 0"/>
                <mass value="0.0001"/>
                <inertia ixx="0.001" ixy="0" ixz="0" iyy="0.001" iyz="0" izz="0.001"/>
            </inertial>
        </link>
        <joint name="lwrist_rz" type="fixed">
            <origin xyz="0 0 0" rpy="0 0 0"/>
            <parent link="lwrist_ry"/>
            <child link="lwrist_rz"/>
        </joint>
        <link name="lwrist">
            <inertial>
                <origin xyz="0.04 0 0" rpy="0 0 0"/>
                <mass value="0.5"/>
                <inertia ixx="0.001" ixy="0" ixz="0" iyy="0.001" iyz="0" izz="0.001"/>
            </inertial>
            <collision name="lwrist">
                <origin xyz="0.04 0 0" rpy="0 0 0"/>
                <geometry>
                    <sphere radius="0.04"/>
                </geometry>
            </collision>
        </link>
        <joint name="lwrist" type="fixed">
            <origin xyz="0 0 0" rpy="0 0 0"/>
            <parent link="lwrist_rz"/>
            <child link="lwrist"/>
        </joint>
        <link name="rclavicle_rx">
            <inertial>
                <origin xyz="0 0 0" rpy="0 0 0"/>
                <mass value="0.0001"/>
                <inertia ixx="0.001" ixy="0" ixz="0" iyy="0.001" iyz="0" izz="0.001"/>
            </inertial>
        </link>
        <joint name="rclavicle_rx" type="revolute">
            <origin xyz="-0.08487482 0.12096365 -0.04006233" rpy="0 0 0"/>
            <parent link="chest"/>
            <child link="rclavicle_rx"/>
            <limit effort="1000.0" lower="-3.14" upper="3.14" velocity="0.5" />
            <axis xyz="1 0 0"/>
        </joint>
        <link name="rclavicle_ry">
            <inertial>
                <origin xyz="0 0 0" rpy="0 0 0"/>
                <mass value="0.0001"/>
                <inertia ixx="0.001" ixy="0" ixz="0" iyy="0.001" iyz="0" izz="0.001"/>
            </inertial>
        </link>
        <joint name="rclavicle_ry" type="revolute">
            <origin xyz="0 0 0" rpy="0 0 0"/>
            <parent link="rclavicle_rx"/>
            <child link="rclavicle_ry"/>
            <limit effort="1000.0" lower="-3.14" upper="3.14" velocity="0.5" />
            <axis xyz="0 1 0"/>
        </joint>
        <link name="rclavicle_rz">
            <inertial>
                <origin xyz="0 0 0" rpy="0 0 0"/>
                <mass value="0.0001"/>
                <inertia ixx="0.001" ixy="0" ixz="0" iyy="0.001" iyz="0" izz="0.001"/>
            </inertial>
        </link>
        <joint name="rclavicle_rz" type="revolute">
            <origin xyz="0 0 0" rpy="0 0 0"/>
            <parent link="rclavicle_ry"/>
            <child link="rclavicle_rz"/>
            <limit effort="1000.0" lower="-3.14" upper="3.14" velocity="0.5" />
            <axis xyz="0 0 1"/>
        </joint>
        <link name="rclavicle">
            <inertial>
                <origin xyz="-0.050191298 0.014807105 -0.0054457765" rpy="0 0 0"/>
                <mass value="1"/>
                <inertia ixx="0.001" ixy="0" ixz="0" iyy="0.001" iyz="0" izz="0.001"/>
            </inertial>
            <collision name="rclavicle">
                <origin xyz="-0.050191298 0.014807105 -0.0054457765" rpy="-1.9232233026565768 -1.2662424025482515 1.6213581265739896"/>
                <geometry>
                    <capsule radius="0.04" length="0.02522496700286865"/>
                </geometry>
            </collision>
        </link>
        <joint name="rclavicle" type="fixed">
            <origin xyz="0 0 0" rpy="0 0 0"/>
            <parent link="rclavicle_rz"/>
            <child link="rclavicle"/>
        </joint>
        <link name="rshoulder_rx">
            <inertial>
                <origin xyz="0 0 0" rpy="0 0 0"/>
                <mass value="0.0001"/>
                <inertia ixx="0.001" ixy="0" ixz="0" iyy="0.001" iyz="0" izz="0.001"/>
            </inertial>
        </link>
        <joint name="rshoulder_rx" type="revolute">
            <origin xyz="-0.100382596 0.02961421 -0.010891553" rpy="0 0 0"/>
            <parent link="rclavicle"/>
            <child link="rshoulder_rx"/>
            <limit effort="1000.0" lower="-3.14" upper="3.14" velocity="0.5" />
            <axis xyz="1 0 0"/>
        </joint>
        <link name="rshoulder_ry">
            <inertial>
                <origin xyz="0 0 0" rpy="0 0 0"/>
                <mass value="0.0001"/>
                <inertia ixx="0.001" ixy="0" ixz="0" iyy="0.001" iyz="0" izz="0.001"/>
            </inertial>
        </link>
        <joint name="rshoulder_ry" type="revolute">
            <origin xyz="0 0 0" rpy="0 0 0"/>
            <parent link="rshoulder_rx"/>
            <child link="rshoulder_ry"/>
            <limit effort="1000.0" lower="-3.14" upper="3.14" velocity="0.5" />
            <axis xyz="0 1 0"/>
        </joint>
        <link name="rshoulder_rz">
            <inertial>
                <origin xyz="0 0 0" rpy="0 0 0"/>
                <mass value="0.0001"/>
                <inertia ixx="0.001" ixy="0" ixz="0" iyy="0.001" iyz="0" izz="0.001"/>
            </inertial>
        </link>
        <joint name="rshoulder_rz" type="revolute">
            <origin xyz="0 0 0" rpy="0 0 0"/>
            <parent link="rshoulder_ry"/>
            <child link="rshoulder_rz"/>
            <limit effort="1000.0" lower="-3.14" upper="3.14" velocity="0.5" />
            <axis xyz="0 0 1"/>
        </joint>
        <link name="rshoulder">
            <inertial>
                <origin xyz="-0.12117733 -0.004410453 -0.011007994" rpy="0 0 0"/>
                <mass value="2"/>
                <inertia ixx="0.001" ixy="0" ixz="0" iyy="0.001" iyz="0" izz="0.001"/>
            </inertial>
            <collision name="rshoulder">
                <origin xyz="-0.12117733 -0.004410453 -0.011007994" rpy="0 0 0"/>
                <geometry>
                    <box size="0.2235124069452286 0.05 0.05"/>
                </geometry>
            </collision>
        </link>
        <joint name="rshoulder" type="fixed">
            <origin xyz="0 0 0" rpy="0 0 0"/>
            <parent link="rshoulder_rz"/>
            <child link="rshoulder"/>
        </joint>
        <link name="relbow_rx">
            <inertial>
                <origin xyz="0 0 0" rpy="0 0 0"/>
                <mass value="0.0001"/>
                <inertia ixx="0.001" ixy="0" ixz="0" iyy="0.001" iyz="0" izz="0.001"/>
            </inertial>
        </link>
        <joint name="relbow_rx" type="revolute">
            <origin xyz="-0.24235466 -0.008820906 -0.022015989" rpy="0 0 0"/>
            <parent link="rshoulder"/>
            <child link="relbow_rx"/>
            <limit effort="1000.0" lower="-3.14" upper="3.14" velocity="0.5" />
            <axis xyz="1 0 0"/>
        </joint>
        <link name="relbow_ry">
            <inertial>
                <origin xyz="0 0 0" rpy="0 0 0"/>
                <mass value="0.0001"/>
                <inertia ixx="0.001" ixy="0" ixz="0" iyy="0.001" iyz="0" izz="0.001"/>
            </inertial>
        </link>
        <joint name="relbow_ry" type="revolute">
            <origin xyz="0 0 0" rpy="0 0 0"/>
            <parent link="relbow_rx"/>
            <child link="relbow_ry"/>
            <limit effort="1000.0" lower="-3.14" upper="3.14" velocity="0.5" />
            <axis xyz="0 1 0"/>
        </joint>
        <link name="relbow_rz">
            <inertial>
                <origin xyz="0 0 0" rpy="0 0 0"/>
                <mass value="0.0001"/>
                <inertia ixx="0.001" ixy="0" ixz="0" iyy="0.001" iyz="0" izz="0.001"/>
            </inertial>
        </link>
        <joint name="relbow_rz" type="revolute">
            <origin xyz="0 0 0" rpy="0 0 0"/>
            <parent link="relbow_ry"/>
            <child link="relbow_rz"/>
            <limit effort="1000.0" lower="-3.14" upper="3.14" velocity="0.5" />
            <axis xyz="0 0 1"/>
        </joint>
        <link name="relbow">
            <inertial>
                <origin xyz="-0.12165469 0.0029384643 -0.002505228" rpy="0 0 0"/>
                <mass value="1"/>
                <inertia ixx="0.001" ixy="0" ixz="0" iyy="0.001" iyz="0" izz="0.001"/>
            </inertial>
            <collision name="relbow">
                <origin xyz="-0.12165469 0.0029384643 -0.002505228" rpy="0 0 0"/>
                <geometry>
                    <box size="0.22343191087245942 0.05 0.05"/>
                </geometry>
            </collision>
        </link>
        <joint name="relbow" type="fixed">
            <origin xyz="0 0 0" rpy="0 0 0"/>
            <parent link="relbow_rz"/>
            <child link="relbow"/>
        </joint>
        <link name="rwrist_rx">
            <inertial>
                <origin xyz="0 0 0" rpy="0 0 0"/>
                <mass value="0.0001"/>
                <inertia ixx="0.001" ixy="0" ixz="0" iyy="0.001" iyz="0" izz="0.001"/>
            </inertial>
        </link>
        <joint name="rwrist_rx" type="fixed">
            <origin xyz="-0.24330938 0.0058769286 -0.005010456" rpy="0 0 0"/>
            <parent link="relbow"/>
            <child link="rwrist_rx"/>
        </joint>
        <link name="rwrist_ry">
            <inertial>
                <origin xyz="0 0 0" rpy="0 0 0"/>
                <mass value="0.0001"/>
                <inertia ixx="0.001" ixy="0" ixz="0" iyy="0.001" iyz="0" izz="0.001"/>
            </inertial>
        </link>
        <joint name="rwrist_ry" type="fixed">
            <origin xyz="0 0 0" rpy="0 0 0"/>
            <parent link="rwrist_rx"/>
            <child link="rwrist_ry"/>
        </joint>
        <link name="rwrist_rz">
            <inertial>
                <origin xyz="0 0 0" rpy="0 0 0"/>
                <mass value="0.0001"/>
                <inertia ixx="0.001" ixy="0" ixz="0" iyy="0.001" iyz="0" izz="0.001"/>
            </inertial>
        </link>
        <joint name="rwrist_rz" type="fixed">
            <origin xyz="0 0 0" rpy="0 0 0"/>
            <parent link="rwrist_ry"/>
            <child link="rwrist_rz"/>
        </joint>
        <link name="rwrist">
            <inertial>
                <origin xyz="-0.04 0 0" rpy="0 0 0"/>
                <mass value="0.5"/>
                <inertia ixx="0.001" ixy="0" ixz="0" iyy="0.001" iyz="0" izz="0.001"/>
            </inertial>
            <collision name="rwrist">
                <origin xyz="-0.04 0 0" rpy="0 0 0"/>
                <geometry>
                    <sphere radius="0.04"/>
                </geometry>
            </collision>
        </link>
        <joint name="rwrist" type="fixed">
            <origin xyz="0 0 0" rpy="0 0 0"/>
            <parent link="rwrist_rz"/>
            <child link="rwrist"/>
        </joint>
        <link name = "ltoe" >
		<inertial>
			<origin rpy = "0 0 0" xyz = "0.000000 0.000000 0.000000" />
			<mass value = "0.000100" />
			<inertia ixx = "0.001000" ixy = "0.000000" ixz = "0.000000" iyy = "0.001000" iyz = "0.000000" izz = "0.001000" />
		</inertial>
		<collision>
			<origin rpy = "0 1.54 0" xyz = "0 0 0" />
			<geometry>
				<cylinder length = "0.08" radius = "0.0050000" />
			</geometry>
		</collision>
	</link>
	<joint name = "ltoe" type = "revolute" >
		<parent link = "lankle" />
		<child link = "ltoe" />
		<origin rpy = "0.000000 0.000000 0.000000" xyz = "0 0 0" />
		<limit effort = "1000.000000" lower = "-3.140000" upper = "3.140000" velocity = "0.500000" />
		<axis xyz = "0.000000 1.000000 0.000000" />
	</joint>
	<link name = "lheel">
		<inertial>
			<origin rpy = "0 0 0"  xyz = "0 0 0" />
			<mass value =  "0.0001" />
			<inertia ixx = "0.1" ixy = "0" ixz = "0" iyy = "0.1" iyz = "0" izz = "0.1" />
		</inertial>
		<collision>
			<origin rpy = "0 1.54 0"  xyz = "0 0 0" />
			<geometry>
				<cylinder length="0.08" radius="0.005"/>
			</geometry>
		</collision>
	</link>
	<joint name="lheel" type="revolute">
		<parent link = "ltoe" />
		<child link = "lheel" />
		<origin rpy = "0 0 0" xyz ="0 0 -0.185"  /> 
		<limit effort = "1000.000000" lower = "-3.140000" upper = "3.140000" velocity = "0.500000" />
		<axis xyz = "0.0 1.0 0.0" />
	</joint>
    </robot>